<?xml version="1.0"?>
<robot name="threeseg">
  <link name = "rover"/>
  <link name="base">
    <visual>
      <origin xyz="0 0 0" rpy="0 0 0"/>
      <geometry>
        <box size="0.30 0.50 0.30"/>     
     </geometry>
     <material name="black_metal">
        <color rgba="0.1 0.1 0.1 1"/>
     </material>
    </visual>
  </link>  
  <link name="link1">
    <visual>
      <origin xyz="0 0 1.655" rpy="0 0 0"/>
      <geometry>
        <cylinder length="3.31" radius="0.1"/>     
     </geometry>
    </visual>
  </link>
  <link name="link2">
    <visual>
      <origin xyz="0 0 1.21" rpy="0 0 0"/>
      <geometry>
        <cylinder length="2.42" radius="0.1"/>     
      </geometry>
    </visual>
  </link>
  <link name="gripper_base">
    <visual>
      <origin xyz="0 0 0" rpy="0 0 0"/>
      <geometry>
        <box size="0 0 0"/>
      </geometry>
    </visual>
  </link>
  <link name="gripper">
    <visual>
      <origin xyz="0 0 0.165" rpy="0 0 0"/>
      <geometry>
        <box size="0.1 0.1 0.23"/>
      </geometry>
    </visual>
  </link>
  <joint name="joint1" type="continuous">
    <parent link="rover" />
    <child link="base" />
    <limit effort="30" velocity="1.0" lower="-1.570795" upper="1.570795" />
    <origin xyz="0 0 0" rpy="0 0 0" />
    <axis xyz="0 1 0" />
  </joint>
  <joint name="joint2" type="continuous">
    <parent link="base" />
    <child link="link1" />
    <limit effort="30" velocity="1.0" lower="-1.570795" upper="1.570795" />
    <origin xyz="0 0 0" rpy="0 0 0" />
    <axis xyz="0 0 1" />
  </joint>
  <joint name="joint3" type="continuous">
    <parent link="link1" />
    <child link="link2" />
    <limit effort="30" velocity="1.0" lower="-1.570795" upper="1.570795" />
    <origin xyz="0 0 3.31" rpy="0 0 0" />
    <axis xyz="1 0 0" />
  </joint>
  <joint name="joint4" type="continuous">
    <parent link="link2" />
    <child link="gripper_base" />
    <limit effort="30" velocity="1.0" lower="-1.570795" upper="1.570795" />
    <origin xyz="0 0 2.42" rpy="0 0 0" />
    <axis xyz="1 0 0" />
  </joint>
  <joint name="joint5" type="continuous">
    <parent link="gripper_base" />
    <child link="gripper" />
    <limit effort="30" velocity="1.0" lower="-1.570795" upper="1.570795" />
    <origin xyz="0 0 0" rpy="0 0 0" />
    <axis xyz="0 0 1" />
  </joint>
</robot>